Workbook

Sheet Remove Duplicate Company Na (2)
A1: Company
A2: Spirit of Tasmania
A3: Total Tools
A4: Decjuba
A5: Australian Department of the Environment
A6: Tasmanian Government
A7: integratedliving
A8: Department of Agriculture & Water Resources
A9: Possability
A10: BestStart Educare
A11: University of Tasmania
A12: JPS Medical Recruitment
... A2655: Arise Recruitment
A2656: 1300
A2657: Workforce International Pty Ltd
A2658: Employment Matters
A2659: Fenner Dunlop
A2660: Champion Crewing & Concierge
A2661: Dental Connect Recruitment
A2662: Australian Health Professionals
A2663: Trinity College Gladstone
A2664: CBC Staff Selection
A2665: Alchemy Recruitment Consulting
A2666: Your Resourcing Group Pty Ltd
A2667: Grow Money Pty Ltd
A2668: GO2 Recruitment
... A3089: CMW Geosciences

Sheet Raw Data
A1: Title | B1: Company | D1: Location | E1: State | F1: Category | G1: Level
A2: CUSTOMER SERVICES OFFICER (PPT) x2 | B2: Spirit of Tasmania | C2: DEVONPORT TAS | D2: =LEFT(C2, LEN(C2)-3) -> DEVONPORT | E2: =RIGHT(C2,3) -> TAS | F2: Administration & Office Support | G2: Team member
A3: Sales Assistant | B3: Total Tools | C3: INVERMAY TAS | D3: =LEFT(C3, LEN(C3)-3) -> INVERMAY | E3: =RIGHT(C3,3) -> TAS | F3: Retail & Consumer Products | G3: Assistant level
A4: Retail Assistant | B4: Decjuba | C4: HOBART TAS | D4: =LEFT(C4, LEN(C4)-3) -> HOBART | E4: =RIGHT(C4,3) -> TAS | F4: Retail & Consumer Products | G4: Assistant level
A5: Visitor Services Officer | B5: Australian Department of the Environment | C5: NATIONAL PARK TAS | D5: =LEFT(C5, LEN(C5)-3) -> NATIONAL PARK | E5: =RIGHT(C5,3) -> TAS | F5: Administration & Office Support | G5: Team Leader
A6: Teacher under Supervision | B6: Tasmanian Government | C6: HOBART TAS | D6: =LEFT(C6, LEN(C6)-3) -> HOBART | E6: =RIGHT(C6,3) -> TAS | F6: Education & Training | G6: Team member
A7: Support Worker - Hobart | B7: integratedliving | C7: KINGSTON TAS | D7: =LEFT(C7, LEN(C7)-3) -> KINGSTON | E7: =RIGHT(C7,3) -> TAS | F7: Trades & Services | G7: Team member
A8: Legal Practitioner | B8: Tasmanian Government | C8: LAUNCESTON TAS | D8: =LEFT(C8, LEN(C8)-3) -> LAUNCESTON | E8: =RIGHT(C8,3) -> TAS | F8: Legal | G8: Team member
A9: Visitor Services Officer | B9: Department of Agriculture & Water Resources | C9: NATIONAL PARK TAS | D9: =LEFT(C9, LEN(C9)-3) -> NATIONAL PARK | E9: =RIGHT(C9,3) -> TAS | F9: Administration & Office Support | G9: Team Leader
A10: Project Officer | B10: Tasmanian Government | C10: HOBART TAS | D10: =LEFT(C10, LEN(C10)-3) -> HOBART | E10: =RIGHT(C10,3) -> TAS | F10: Administration & Office Support | G10: Team Leader
A11: Injury Management Officer | B11: Possability | C11: LAUNCESTON TAS | D11: =LEFT(C11, LEN(C11)-3) -> LAUNCESTON | E11: =RIGHT(C11,3) -> TAS | F11: Administration & Office Support | G11: Team Leader
A12: Qualified Teacher and Assistant Manager (BestStart Balclutha... | B12: BestStart Educare | C12: OTAGO TAS | D12: =LEFT(C12, LEN(C12)-3) -> OTAGO | E12: =RIGHT(C12,3) -> TAS | F12: CEO & General Management | G12: Managerial level
A13: Legal Practitioner | B13: Tasmanian Government | C13: BURNIE TAS | D13: =LEFT(C13, LEN(C13)-3) -> BURNIE | E13: =RIGHT(C13,3) -> TAS | F13: Legal | G13: Team member
... A6277: Architectural Graduate | B6277: Arise Recruitment | C6277: TOWNSVILLE QLD | D6277: =LEFT(C6277, LEN(C6277)-3) -> TOWNSVILLE | E6277: =RIGHT(C6277,3) -> QLD | F6277: Other | G6277: Team member
A6278: Health Service Providers | B6278: 1300 | C6278: MOUNT COTTON QLD | D6278: =LEFT(C6278, LEN(C6278)-3) -> MOUNT COTTON | E6278: =RIGHT(C6278,3) -> QLD | F6278: Healthcare & Medical | G6278: Team member
A6279: Pipe Welders | B6279: WhiteCollarBlue | C6279: HEMMANT QLD | D6279: =LEFT(C6279, LEN(C6279)-3) -> HEMMANT | E6279: =RIGHT(C6279,3) -> QLD | F6279: Trades & Services | G6279: Team member
A6280: CURRAGH: L1 TRUCK/ANCIL 7:7 DS:NS | B6280: WorkPac Group | C6280: MACKAY QLD | D6280: =LEFT(C6280, LEN(C6280)-3) -> MACKAY | E6280: =RIGHT(C6280,3) -> QLD | F6280: Other | G6280: Team member
A6281: White Card Laborers | B6281: Job Connect Recruitment | C6281: BRISBANE QLD | D6281: =LEFT(C6281, LEN(C6281)-3) -> BRISBANE | E6281: =RIGHT(C6281,3) -> QLD | F6281: Other | G6281: Team member
A6282: Diesel Fitter Apprenticeship - Blackwater Yard | B6282: Talent Propeller | C6282: BLACKWATER QLD | D6282: =LEFT(C6282, LEN(C6282)-3) -> BLACKWATER | E6282: =RIGHT(C6282,3) -> QLD | F6282: Other | G6282: Team member
A6283: Workplace Trainer | B6283: Davidson Recruitment | C6283: BRISBANE QLD | D6283: =LEFT(C6283, LEN(C6283)-3) -> BRISBANE | E6283: =RIGHT(C6283,3) -> QLD | F6283: Other | G6283: Team member
A6284: Sales Consultant | B6284: AUTOrecruit | C6284: NORTH LAKES QLD | D6284: =LEFT(C6284, LEN(C6284)-3) -> NORTH LAKES | E6284: =RIGHT(C6284,3) -> QLD | F6284: Retail & Consumer Products | G6284: Team member
A6285: LABOURERS REQUIRED - Northern Brisbane - Caboolture - Sunshi... | B6285: Workforce International Pty Ltd | C6285: BRISBANE QLD | D6285: =LEFT(C6285, LEN(C6285)-3) -> BRISBANE | E6285: =RIGHT(C6285,3) -> QLD | F6285: Trades & Services | G6285: Team member
A6286: Maintenance Manager | B6286: Davidson Recruitment | C6286: BRISBANE QLD | D6286: =LEFT(C6286, LEN(C6286)-3) -> BRISBANE | E6286: =RIGHT(C6286,3) -> QLD | F6286: CEO & General Management | G6286: Managerial level
A6287: Osteopath or Chiropractor | B6287: 1300 | C6287: MOUNT COTTON QLD | D6287: =LEFT(C6287, LEN(C6287)-3) -> MOUNT COTTON | E6287: =RIGHT(C6287,3) -> QLD | F6287: Healthcare & Medical | G6287: Team member
A6288: Yardperson | B6288: WorkPac Group | C6288: BRISBANE QLD | D6288: =LEFT(C6288, LEN(C6288)-3) -> BRISBANE | E6288: =RIGHT(C6288,3) -> QLD | F6288: Other | G6288: Team member
A6289: Casual Contact Centre Consultant Family Support | B6289: Davidson Recruitment | C6289: MURARRIE QLD | D6289: =LEFT(C6289, LEN(C6289)-3) -> MURARRIE | E6289: =RIGHT(C6289,3) -> QLD | F6289: Other | G6289: Team member
A6290: State Manager | B6290: Assure Programs | C6290: BRISBANE QLD | D6290: =LEFT(C6290, LEN(C6290)-3) -> BRISBANE | E6290: =RIGHT(C6290,3) -> QLD | F6290: CEO & General Management | G6290: Managerial level
A6291: Beautician | B6291: 1300 | C6291: MOUNT COTTON QLD | D6291: =LEFT(C6291, LEN(C6291)-3) -> MOUNT COTTON | E6291: =RIGHT(C6291,3) -> QLD | F6291: Other | G6291: Team member
A6292: MAINTENANCE FITTER | B6292: Employment Matters | C6292: KINGAROY QLD | D6292: =LEFT(C6292, LEN(C6292)-3) -> KINGAROY | E6292: =RIGHT(C6292,3) -> QLD | F6292: Other | G6292: Team member
A6293: Spare Parts & Accessories Warehouse Controller | B6293: AUTOrecruit | C6293: WYNNUM QLD | D6293: =LEFT(C6293, LEN(C6293)-3) -> WYNNUM | E6293: =RIGHT(C6293,3) -> QLD | F6293: Logistics | G6293: Team member
A6294: Employment Consultant | B6294: CPL - Choice, Passion, Life | C6294: BRISBANE QLD | D6294: =LEFT(C6294, LEN(C6294)-3) -> BRISBANE | E6294: =RIGHT(C6294,3) -> QLD | F6294: Other | G6294: Team member
A6295: Principal Events & Marketing Officer | B6295: Davidson Recruitment | C6295: BRISBANE QLD | D6295: =LEFT(C6295, LEN(C6295)-3) -> BRISBANE | E6295: =RIGHT(C6295,3) -> QLD | F6295: Administration & Office Support | G6295: Team Leader
A6296: Customer Service | International Freight | B6296: Insync Personnel | C6296: BANYO QLD | D6296: =LEFT(C6296, LEN(C6296)-3) -> BANYO | E6296: =RIGHT(C6296,3) -> QLD | F6296: Call Centre & Customer Service | G6296: Team member
A6297: Administration Officer | B6297: Fenner Dunlop | C6297: MURARRIE QLD | D6297: =LEFT(C6297, LEN(C6297)-3) -> MURARRIE | E6297: =RIGHT(C6297,3) -> QLD | F6297: Administration & Office Support | G6297: Team Leader
A6298: Trainer & Assessor - ECEC work placement | B6298: Peak Management & Consulting | C6298: STRATHPINE QLD | D6298: =LEFT(C6298, LEN(C6298)-3) -> STRATHPINE | E6298: =RIGHT(C6298,3) -> QLD | F6298: Other | G6298: Team member
A6299: Skipper Required - Private S/Y - Whitsundays | B6299: Champion Crewing & Concierge | C6299: AIRLIE BEACH QLD | D6299: =LEFT(C6299, LEN(C6299)-3) -> AIRLIE BEACH | E6299: =RIGHT(C6299,3) -> QLD | F6299: Other | G6299: Team member
A6300: Automation Manager | B6300: Entain | C6300: BRISBANE QLD | D6300: =LEFT(C6300, LEN(C6300)-3) -> BRISBANE | E6300: =RIGHT(C6300,3) -> QLD | F6300: CEO & General Management | G6300: Managerial level
A6301: Maintenance Manager - Full Time | B6301: SeaLink | C6301: TOWNSVILLE QLD | D6301: =LEFT(C6301, LEN(C6301)-3) -> TOWNSVILLE | E6301: =RIGHT(C6301,3) -> QLD | F6301: CEO & General Management | G6301: Managerial level
A6302: Junior Dental Assistant (Part-time) #2021813A | B6302: Dental Connect Recruitment | C6302: SOUTH BRISBANE QLD | D6302: =LEFT(C6302, LEN(C6302)-3) -> SOUTH BRISBANE | E6302: =RIGHT(C6302,3) -> QLD | F6302: Healthcare & Medical | G6302: Assistant level
A6303: Enterprise Account Manager (Greenfield) | B6303: AWS Australia Pty Ltd | C6303: BRISBANE QLD | D6303: =LEFT(C6303, LEN(C6303)-3) -> BRISBANE | E6303: =RIGHT(C6303,3) -> QLD | F6303: Accounting | G6303: Managerial level
...

Sheet Company Name
A1: Company
A2: Spirit of Tasmania
A3: Total Tools
A4: Decjuba
A5: Australian Department of the Environment
A6: Tasmanian Government
A7: integratedliving
A8: Tasmanian Government
A9: Department of Agriculture & Water Resources
A10: Tasmanian Government
A11: Possability
A12: BestStart Educare
... A6277: Arise Recruitment
A6278: 1300
A6279: WhiteCollarBlue
A6280: WorkPac Group
A6281: Job Connect Recruitment
A6282: Talent Propeller
A6283: Davidson Recruitment
A6284: AUTOrecruit
A6285: Workforce International Pty Ltd
A6286: Davidson Recruitment
A6287: 1300
A6288: WorkPac Group
A6289: Davidson Recruitment
A6290: Assure Programs
A6291: 1300
A6292: Employment Matters
A6293: AUTOrecruit
A6294: CPL - Choice, Passion, Life
A6295: Davidson Recruitment
A6296: Insync Personnel
A6297: Fenner Dunlop
A6298: Peak Management & Consulting
A6299: Champion Crewing & Concierge
A6300: Entain
A6301: SeaLink
A6302: Dental Connect Recruitment
A6303: AWS Australia Pty Ltd
... A7634: Fonterra

Sheet Remove Duplicate Company Name
A1: Company
A2: Spirit of Tasmania
A3: Total Tools
A4: Decjuba
A5: Australian Department of the Environment
A6: Tasmanian Government
A7: integratedliving
A8: Department of Agriculture & Water Resources
A9: Possability
A10: BestStart Educare
A11: University of Tasmania
A12: JPS Medical Recruitment
... A2655: Arise Recruitment
A2656: 1300
A2657: Workforce International Pty Ltd
A2658: Employment Matters
A2659: Fenner Dunlop
A2660: Champion Crewing & Concierge
A2661: Dental Connect Recruitment
A2662: Australian Health Professionals
A2663: Trinity College Gladstone
A2664: CBC Staff Selection
A2665: Alchemy Recruitment Consulting
A2666: Your Resourcing Group Pty Ltd
A2667: Grow Money Pty Ltd
A2668: GO2 Recruitment
... A3089: CMW Geosciences

Sheet Company Detail
A1: Company
A2: Spirit of Tasmania | B2: =VLOOKUP(A2,'extracted detail'!$A$2:$B$2994,2,FALSE) -> Spirit of Tasmania is more than a ferry to Tasmania & Melbourne. Explore special offers, discounts, sailing schedules and fare & accommodation options here.
A3: Total Tools | B3: =VLOOKUP(A3,'extracted detail'!$A$2:$B$2994,2,FALSE) -> Total Tools, the largest trade tool supplier in Australia, with over 80 stores Nationwide. Total Tools offer the biggest range of professional trade tools, ...
A4: Decjuba | B4: =VLOOKUP(A4,'extracted detail'!$A$2:$B$2994,2,FALSE) -> DECJUBA is effortless & edgy fashion for women. Shop jeans, blazers, skirts, dresses & more. Sign up as a DECJUBA Insider to receive 10% off full price ...
A5: Australian Department of the Environment | B5: =VLOOKUP(A5,'extracted detail'!$A$2:$B$2994,2,FALSE) -> We are an Australian Government department. We work to protect and strengthen our agriculture, water resources, the environment and our heritage.
A6: Tasmanian Government | B6: =VLOOKUP(A6,'extracted detail'!$A$2:$B$2994,2,FALSE) -> Easy access to all Tasmanian Government Services. Jobs · Tenders · Public notices · Have your say · Service Tasmania Online. Government services and ...
A7: integratedliving | B7: =VLOOKUP(A7,'extracted detail'!$A$2:$B$2994,2,FALSE) -> integratedliving provide in-home aged care and disability support to rural, regional and remote Australians. We deliver support customised to your needs.
A8: Department of Agriculture & Water Resources | B8: =VLOOKUP(A8,'extracted detail'!$A$2:$B$2994,2,FALSE) -> Australian Government Department of Agriculture. Implementing policies and programmes to support the agriculture, fisheries, food and forestry industries.
A9: Possability | B9: =VLOOKUP(A9,'extracted detail'!$A$2:$B$2994,2,FALSE) -> Possability is a values-driven disability services provider. Independent living and life skills, SIL, specialist support services.
A10: BestStart Educare | B10: =VLOOKUP(A10,'extracted detail'!$A$2:$B$2994,2,FALSE) -> BestStart has grown into New Zealand's largest provider of early childhood education. We are a New Zealand owned charity with preschools, ...
A11: University of Tasmania | B11: =VLOOKUP(A11,'extracted detail'!$A$2:$B$2994,2,FALSE) -> Thinking of uni? · I'm in school · I was in school a while ago · I'm looking at Postgrad · I want to do a research degree · I'm about to begin my first semester · I'm ...
A12: JPS Medical Recruitment | B12: =VLOOKUP(A12,'extracted detail'!$A$2:$B$2994,2,FALSE) -> If you are looking for a medical recruitment agency in Australia then you must check JPS Medical Recruitment. We provide various medical jobs in Australia.
A13: Nick Scali Furniture | B13: =VLOOKUP(A13,'extracted detail'!$A$2:$B$2994,2,FALSE) -> The experts in quality lounge, dining, and occasional furniture for 50+ years. Over 50 stores Australia wide. Browse online and visit us in-store today.
... A2655: Arise Recruitment | B2655: =VLOOKUP(A2655,'extracted detail'!$A$2:$B$2994,2,FALSE) -> Arise Recruitment - Australia's boutique agency serving the Architecture, Planning and Design Industries.
A2656: 1300 | B2656: =VLOOKUP(A2656,'extracted detail'!$A$2:$B$2994,2,FALSE) -> #N/A
A2657: Workforce International Pty Ltd | B2657: =VLOOKUP(A2657,'extracted detail'!$A$2:$B$2994,2,FALSE) -> WORKFORCE INTERNATIONAL GROUP ... Founded as a specialist Labour Hire company in 1991, Workforce International Group is now a diversified industrial services ...
A2658: Employment Matters | B2658: =VLOOKUP(A2658,'extracted detail'!$A$2:$B$2994,2,FALSE) -> Employee Matters are Sydney based HR Outsource Consultants and Recruitment Experts. Experts assisting employers with HR, recruitment and training, ...
A2659: Fenner Dunlop | B2659: =VLOOKUP(A2659,'extracted detail'!$A$2:$B$2994,2,FALSE) -> Fenner Dunlop Conveyor Belting is the world's largest manufacturer of conveyor belting for mining and industrial applications.
A2660: Champion Crewing & Concierge | B2660: =VLOOKUP(A2660,'extracted detail'!$A$2:$B$2994,2,FALSE) -> Champion Crewing & Concierge - Crew & Yacht Agent specialising in relief & temporary crew and concierge services in the Whitsundays.
A2661: Dental Connect Recruitment | B2661: =VLOOKUP(A2661,'extracted detail'!$A$2:$B$2994,2,FALSE) -> Recruitment Agency | Dental Industry - Permanent & Temp staffing solutions for Dentists & professionals, Practice Managers, Dental Assistants ...
A2662: Australian Health Professionals | B2662: =VLOOKUP(A2662,'extracted detail'!$A$2:$B$2994,2,FALSE) -> Australian Health Professionals (AHP) is a leading Australian medical and healthcare staffing solutions company built on a longstanding history of ...
A2663: Trinity College Gladstone | B2663: =VLOOKUP(A2663,'extracted detail'!$A$2:$B$2994,2,FALSE) -> K-12 Christian Education. PHONE: 07 4839 0500 | EMAIL: admin@trinitygladstone.qld.edu.au | PARENT LOUNGE · Trinity College ... trinity college school.1 ...
A2664: CBC Staff Selection | B2664: =VLOOKUP(A2664,'extracted detail'!$A$2:$B$2994,2,FALSE) -> Employment agency in Cairns, Queensland
A2665: Alchemy Recruitment Consulting | B2665: =VLOOKUP(A2665,'extracted detail'!$A$2:$B$2994,2,FALSE) -> Alchemy Recruitment Consulting (Alchemy) is a workforce solutions provider based in Brisbane specialising in permanent recruitment, labour-hire and managed ...
A2666: Your Resourcing Group Pty Ltd | B2666: =VLOOKUP(A2666,'extracted detail'!$A$2:$B$2994,2,FALSE) -> Your Resourcing is an established, QLD based white-collar recruitment company with offices in Brisbane, Sunshine Coast and the Gold Coast. As tenured specialist ...
A2667: Grow Money Pty Ltd | B2667: =VLOOKUP(A2667,'extracted detail'!$A$2:$B$2994,2,FALSE) -> Find company research, competitor information, contact details & financial data for GROW MONEY PTY LTD of Eight Mile Plains, QUEENSLAND.
A2668: GO2 Recruitment | B2668: =VLOOKUP(A2668,'extracted detail'!$A$2:$B$2994,2,FALSE) -> The GO2 People is a leading provider of vertically integrated recruitment and training services to industry throughout Australia.
... A3089: CMW Geosciences | B3089: =VLOOKUP(A3089,'extracted detail'!$A$2:$B$2994,2,FALSE) -> CMW Geosciences. Address. Tonsley Innovation District CO-HAB Level 1, Administration Building 1 Tonsley Boulevard Tonsley SA 5042. Contact.

Sheet extracted detail
A1: CompanyName | B1: Detail
A2: 1 on 1 Tax | B2: Tax consultant in Highland Park, Queensland
A3: 11 Recruitment | B3: Employment agency in East Perth, Western Australia
A4: 1300 MR SHUTTERS & BLINDS | B4: Outdoor Screen Blinds are the ultimate external blind solution for any outdoor area. 1300 MR SHUTTERS outdoor screen blinds are specially designed for outdoor ...
A5: 1300 Smiles | B5: Dentist in Adelaide city centre, South Australia
A6: 360 Personnel | B6: Recruiter in Bankstown, New South Wales
A7: 365FM | B7: A wholly Australian owned and operated company with offices and resources throughout Australia, 365FM provides national coverage for your business, including ...
A8: 3D Recruit | B8: Leadership Development and Aged Care Recruitment by Above and Beyond Group. Transformational workforce solutions. Specialists in Aged Care & Community ...
A9: 4Mile Pty Ltd | B9: Call center in North Strathfield, New South Wales
A10: 4Site | B10: Kitchen furniture store in Canberra
A11: 6 Head | B11: Welcome to 6HEAD, Sydney's premium waterfront restaurant featuring the finest steaks from respected local purveyors & a hand-selected wine list. Book today.
A12: 9D Care | B12: 9D Care is a Private Home Care Provider offering Home Care Services in Melbourne, including NDIS Personal Care Services and In Home Disability Support.
... A2994: Zurich Insurance | B2994: Zurich Financial Services Australia Ltd is the only global financial services company operating in Australia under a single brand in our core lines of ...
